2025-03-07 18:11:05,632 INFO    Thread-622 (_run_job):34492 [wandb_setup.py:_flush():67] Current SDK version is 0.19.7
2025-03-07 18:11:05,633 INFO    Thread-622 (_run_job):34492 [wandb_setup.py:_flush():67] Configure stats pid to 34492
2025-03-07 18:11:05,633 INFO    Thread-622 (_run_job):34492 [wandb_setup.py:_flush():67] Loading settings from C:\Users\sudha\.config\wandb\settings
2025-03-07 18:11:05,633 INFO    Thread-622 (_run_job):34492 [wandb_setup.py:_flush():67] Loading settings from c:\Users\sudha\Desktop\My Data\Education\IITM\2nd sem\Intro to DL\Assignments\Deep-Learning-Assignmnent-1-DA24M023\wandb\settings
2025-03-07 18:11:05,633 INFO    Thread-622 (_run_job):34492 [wandb_setup.py:_flush():67] Loading settings from environment variables
2025-03-07 18:11:05,633 INFO    Thread-622 (_run_job):34492 [wandb_init.py:setup_run_log_directory():647] Logging user logs to c:\Users\sudha\Desktop\My Data\Education\IITM\2nd sem\Intro to DL\Assignments\Deep-Learning-Assignmnent-1-DA24M023\wandb\run-20250307_181105-fvjwijlm\logs\debug.log
2025-03-07 18:11:05,633 INFO    Thread-622 (_run_job):34492 [wandb_init.py:setup_run_log_directory():648] Logging internal logs to c:\Users\sudha\Desktop\My Data\Education\IITM\2nd sem\Intro to DL\Assignments\Deep-Learning-Assignmnent-1-DA24M023\wandb\run-20250307_181105-fvjwijlm\logs\debug-internal.log
2025-03-07 18:11:05,633 INFO    Thread-622 (_run_job):34492 [wandb_init.py:monkeypatch_ipython():599] configuring jupyter hooks <wandb.sdk.wandb_init._WandbInit object at 0x00000217DCE1AFD0>
2025-03-07 18:11:05,633 INFO    Thread-622 (_run_job):34492 [wandb_init.py:init():761] calling init triggers
2025-03-07 18:11:05,633 INFO    Thread-622 (_run_job):34492 [wandb_init.py:init():766] wandb.init called with sweep_config: {'activation': 'sigmoid', 'batch_size': 16, 'epochs': 10, 'hidden_layers': 4, 'hidden_size': 128, 'learning_rate': 0.001, 'optimizer': 'nesterov', 'weight_decay': 0.0005, 'weight_init': 'xavier'}
config: {'_wandb': {}}
2025-03-07 18:11:05,633 INFO    Thread-622 (_run_job):34492 [wandb_init.py:init():784] starting backend
2025-03-07 18:11:05,633 INFO    Thread-622 (_run_job):34492 [wandb_init.py:init():788] sending inform_init request
2025-03-07 18:11:05,635 INFO    Thread-622 (_run_job):34492 [backend.py:_multiprocessing_setup():97] multiprocessing start_methods=spawn, using: spawn
2025-03-07 18:11:05,636 INFO    Thread-622 (_run_job):34492 [wandb_init.py:init():803] backend started and connected
2025-03-07 18:11:05,636 INFO    Thread-622 (_run_job):34492 [wandb_run.py:_config_callback():1261] config_cb None None {'activation': 'sigmoid', 'batch_size': 16, 'epochs': 10, 'hidden_layers': 4, 'hidden_size': 128, 'learning_rate': 0.001, 'optimizer': 'nesterov', 'weight_decay': 0.0005, 'weight_init': 'xavier'}
2025-03-07 18:11:05,638 INFO    Thread-622 (_run_job):34492 [wandb_run.py:_label_probe_notebook():1204] probe notebook
2025-03-07 18:11:05,638 INFO    Thread-622 (_run_job):34492 [wandb_run.py:_label_probe_notebook():1214] Unable to probe notebook: 'charmap' codec can't decode byte 0x81 in position 897: character maps to <undefined>
2025-03-07 18:11:05,638 INFO    Thread-622 (_run_job):34492 [wandb_init.py:init():896] updated telemetry
2025-03-07 18:11:05,703 INFO    Thread-622 (_run_job):34492 [wandb_init.py:init():920] communicating run to backend with 90.0 second timeout
2025-03-07 18:11:06,756 INFO    Thread-622 (_run_job):34492 [wandb_init.py:init():995] starting run threads in backend
2025-03-07 18:11:06,934 INFO    Thread-622 (_run_job):34492 [wandb_run.py:_console_start():2377] atexit reg
2025-03-07 18:11:06,934 INFO    Thread-622 (_run_job):34492 [wandb_run.py:_redirect():2227] redirect: wrap_raw
2025-03-07 18:11:06,934 INFO    Thread-622 (_run_job):34492 [wandb_run.py:_redirect():2292] Wrapping output streams.
2025-03-07 18:11:06,934 INFO    Thread-622 (_run_job):34492 [wandb_run.py:_redirect():2317] Redirects installed.
2025-03-07 18:11:06,934 INFO    Thread-622 (_run_job):34492 [wandb_init.py:init():1037] run started, returning control to user process
2025-03-07 18:12:25,676 INFO    Thread-26 (_heartbeat):34492 [retry.py:__call__():175] Retry attempt failed:
Traceback (most recent call last):
  File "c:\Users\sudha\AppData\Local\Programs\Python\Python311\Lib\site-packages\urllib3\connection.py", line 198, in _new_conn
    sock = connection.create_connection(
           ^^^^^^^^^^^^^^^^^^^^^^^^^^^^^
  File "c:\Users\sudha\AppData\Local\Programs\Python\Python311\Lib\site-packages\urllib3\util\connection.py", line 60, in create_connection
    for res in socket.getaddrinfo(host, port, family, socket.SOCK_STREAM):
               ^^^^^^^^^^^^^^^^^^^^^^^^^^^^^^^^^^^^^^^^^^^^^^^^^^^^^^^^^^
  File "c:\Users\sudha\AppData\Local\Programs\Python\Python311\Lib\socket.py", line 962, in getaddrinfo
    for res in _socket.getaddrinfo(host, port, family, type, proto, flags):
               ^^^^^^^^^^^^^^^^^^^^^^^^^^^^^^^^^^^^^^^^^^^^^^^^^^^^^^^^^^^
socket.gaierror: [Errno 11001] getaddrinfo failed

The above exception was the direct cause of the following exception:

Traceback (most recent call last):
  File "c:\Users\sudha\AppData\Local\Programs\Python\Python311\Lib\site-packages\urllib3\connectionpool.py", line 787, in urlopen
    response = self._make_request(
               ^^^^^^^^^^^^^^^^^^^
  File "c:\Users\sudha\AppData\Local\Programs\Python\Python311\Lib\site-packages\urllib3\connectionpool.py", line 488, in _make_request
    raise new_e
  File "c:\Users\sudha\AppData\Local\Programs\Python\Python311\Lib\site-packages\urllib3\connectionpool.py", line 464, in _make_request
    self._validate_conn(conn)
  File "c:\Users\sudha\AppData\Local\Programs\Python\Python311\Lib\site-packages\urllib3\connectionpool.py", line 1093, in _validate_conn
    conn.connect()
  File "c:\Users\sudha\AppData\Local\Programs\Python\Python311\Lib\site-packages\urllib3\connection.py", line 704, in connect
    self.sock = sock = self._new_conn()
                       ^^^^^^^^^^^^^^^^
  File "c:\Users\sudha\AppData\Local\Programs\Python\Python311\Lib\site-packages\urllib3\connection.py", line 205, in _new_conn
    raise NameResolutionError(self.host, self, e) from e
urllib3.exceptions.NameResolutionError: <urllib3.connection.HTTPSConnection object at 0x00000217DCEB31D0>: Failed to resolve 'api.wandb.ai' ([Errno 11001] getaddrinfo failed)

The above exception was the direct cause of the following exception:

Traceback (most recent call last):
  File "c:\Users\sudha\AppData\Local\Programs\Python\Python311\Lib\site-packages\requests\adapters.py", line 667, in send
    resp = conn.urlopen(
           ^^^^^^^^^^^^^
  File "c:\Users\sudha\AppData\Local\Programs\Python\Python311\Lib\site-packages\urllib3\connectionpool.py", line 841, in urlopen
    retries = retries.increment(
              ^^^^^^^^^^^^^^^^^^
  File "c:\Users\sudha\AppData\Local\Programs\Python\Python311\Lib\site-packages\urllib3\util\retry.py", line 519, in increment
    raise MaxRetryError(_pool, url, reason) from reason  # type: ignore[arg-type]
    ^^^^^^^^^^^^^^^^^^^^^^^^^^^^^^^^^^^^^^^^^^^^^^^^^^^
urllib3.exceptions.MaxRetryError: HTTPSConnectionPool(host='api.wandb.ai', port=443): Max retries exceeded with url: /graphql (Caused by NameResolutionError("<urllib3.connection.HTTPSConnection object at 0x00000217DCEB31D0>: Failed to resolve 'api.wandb.ai' ([Errno 11001] getaddrinfo failed)"))

During handling of the above exception, another exception occurred:

Traceback (most recent call last):
  File "c:\Users\sudha\AppData\Local\Programs\Python\Python311\Lib\site-packages\wandb\sdk\lib\retry.py", line 134, in __call__
    result = self._call_fn(*args, **kwargs)
             ^^^^^^^^^^^^^^^^^^^^^^^^^^^^^^
  File "c:\Users\sudha\AppData\Local\Programs\Python\Python311\Lib\site-packages\wandb\sdk\internal\internal_api.py", line 398, in execute
    return self.client.execute(*args, **kwargs)  # type: ignore
           ^^^^^^^^^^^^^^^^^^^^^^^^^^^^^^^^^^^^
  File "c:\Users\sudha\AppData\Local\Programs\Python\Python311\Lib\site-packages\wandb\vendor\gql-0.2.0\wandb_gql\client.py", line 52, in execute
    result = self._get_result(document, *args, **kwargs)
             ^^^^^^^^^^^^^^^^^^^^^^^^^^^^^^^^^^^^^^^^^^^
  File "c:\Users\sudha\AppData\Local\Programs\Python\Python311\Lib\site-packages\wandb\vendor\gql-0.2.0\wandb_gql\client.py", line 60, in _get_result
    return self.transport.execute(document, *args, **kwargs)
           ^^^^^^^^^^^^^^^^^^^^^^^^^^^^^^^^^^^^^^^^^^^^^^^^^
  File "c:\Users\sudha\AppData\Local\Programs\Python\Python311\Lib\site-packages\wandb\sdk\lib\gql_request.py", line 58, in execute
    request = self.session.post(self.url, **post_args)
              ^^^^^^^^^^^^^^^^^^^^^^^^^^^^^^^^^^^^^^^^
  File "c:\Users\sudha\AppData\Local\Programs\Python\Python311\Lib\site-packages\requests\sessions.py", line 637, in post
    return self.request("POST", url, data=data, json=json, **kwargs)
           ^^^^^^^^^^^^^^^^^^^^^^^^^^^^^^^^^^^^^^^^^^^^^^^^^^^^^^^^^
  File "c:\Users\sudha\AppData\Local\Programs\Python\Python311\Lib\site-packages\requests\sessions.py", line 589, in request
    resp = self.send(prep, **send_kwargs)
           ^^^^^^^^^^^^^^^^^^^^^^^^^^^^^^
  File "c:\Users\sudha\AppData\Local\Programs\Python\Python311\Lib\site-packages\requests\sessions.py", line 703, in send
    r = adapter.send(request, **kwargs)
        ^^^^^^^^^^^^^^^^^^^^^^^^^^^^^^^
  File "c:\Users\sudha\AppData\Local\Programs\Python\Python311\Lib\site-packages\requests\adapters.py", line 700, in send
    raise ConnectionError(e, request=request)
requests.exceptions.ConnectionError: HTTPSConnectionPool(host='api.wandb.ai', port=443): Max retries exceeded with url: /graphql (Caused by NameResolutionError("<urllib3.connection.HTTPSConnection object at 0x00000217DCEB31D0>: Failed to resolve 'api.wandb.ai' ([Errno 11001] getaddrinfo failed)"))
2025-03-07 18:13:11,947 INFO    Thread-622 (_run_job):34492 [wandb_run.py:_finish():2112] finishing run da24m023-indian-institute-of-technology-madras/fashion-mnist-nn/fvjwijlm
2025-03-07 18:13:11,948 ERROR   Thread-622 (_run_job):34492 [jupyter.py:save_history():450] Run pip install nbformat to save notebook history
2025-03-07 18:13:11,948 INFO    Thread-622 (_run_job):34492 [jupyter.py:save_ipynb():386] not saving jupyter notebook
2025-03-07 18:13:11,948 INFO    Thread-622 (_run_job):34492 [wandb_init.py:_jupyter_teardown():581] cleaning up jupyter logic
2025-03-07 18:13:11,948 INFO    Thread-622 (_run_job):34492 [wandb_run.py:_atexit_cleanup():2342] got exitcode: 0
2025-03-07 18:13:11,948 INFO    Thread-622 (_run_job):34492 [wandb_run.py:_restore():2324] restore
2025-03-07 18:13:11,948 INFO    Thread-622 (_run_job):34492 [wandb_run.py:_restore():2330] restore done
2025-03-07 18:16:18,392 INFO    MsgRouterThr:34492 [mailbox.py:close():115] Closing mailbox, abandoning 1 handles.
2025-03-07 18:16:18,392 INFO    Thread-622 (_run_job):34492 [wandb_run.py:_footer_history_summary_info():3958] rendering history
2025-03-07 18:16:18,393 INFO    Thread-622 (_run_job):34492 [wandb_run.py:_footer_history_summary_info():3990] rendering summary
2025-03-07 18:16:18,395 INFO    Thread-622 (_run_job):34492 [wandb_run.py:_footer_sync_info():3919] logging synced files
