Epoch 1/1:   0%|                                                                                                                   | 0/3375 [00:00<?, ?it/s]
Traceback (most recent call last):
  File "C:\Users\sudha\Desktop\My Data\Education\IITM\2nd sem\Intro to DL\Assignments\Deep-Learning-Assignmnent-1-DA24M023\train.py", line 152, in <module>
    main()
  File "C:\Users\sudha\Desktop\My Data\Education\IITM\2nd sem\Intro to DL\Assignments\Deep-Learning-Assignmnent-1-DA24M023\train.py", line 144, in main
    run_single_experiment(args)
  File "C:\Users\sudha\Desktop\My Data\Education\IITM\2nd sem\Intro to DL\Assignments\Deep-Learning-Assignmnent-1-DA24M023\train.py", line 56, in run_single_experiment
    train_losses, train_accs, val_losses, val_accs = train(model, x_train, y_train, args.batch_size, args.epochs, X_val, y_val, loss_fn=args.loss)
                                                     ^^^^^^^^^^^^^^^^^^^^^^^^^^^^^^^^^^^^^^^^^^^^^^^^^^^^^^^^^^^^^^^^^^^^^^^^^^^^^^^^^^^^^^^^^^^^^
  File "C:\Users\sudha\Desktop\My Data\Education\IITM\2nd sem\Intro to DL\Assignments\Deep-Learning-Assignmnent-1-DA24M023\trainer.py", line 39, in train
    loss = model.compute_loss(y_pred, y_batch, loss_fn)
           ^^^^^^^^^^^^^^^^^^^^^^^^^^^^^^^^^^^^^^^^^^^^
  File "C:\Users\sudha\Desktop\My Data\Education\IITM\2nd sem\Intro to DL\Assignments\Deep-Learning-Assignmnent-1-DA24M023\neural_network.py", line 195, in compute_loss
    raise ValueError(f"Loss function {loss_fn} not supported")
ValueError: Loss function mean_squeared_error not supported
