2025-03-04 16:22:41,879 INFO    MainThread:22524 [wandb_init.py:setup_run_log_directory():647] Logging user logs to c:\Users\sudha\Desktop\My Data\Education\IITM\2nd sem\Intro to DL\Assignments\Deep-Learning-Assignmnent-1-DA24M023\wandb\run-20250304_162241-ffe1nnm5\logs\debug.log
2025-03-04 16:22:41,879 INFO    MainThread:22524 [wandb_init.py:setup_run_log_directory():648] Logging internal logs to c:\Users\sudha\Desktop\My Data\Education\IITM\2nd sem\Intro to DL\Assignments\Deep-Learning-Assignmnent-1-DA24M023\wandb\run-20250304_162241-ffe1nnm5\logs\debug-internal.log
2025-03-04 16:22:41,879 INFO    MainThread:22524 [wandb_init.py:init():761] calling init triggers
2025-03-04 16:22:41,879 INFO    MainThread:22524 [wandb_init.py:init():766] wandb.init called with sweep_config: {}
config: {'learning_rate': 0.02, 'architecture': 'CNN', 'dataset': 'CIFAR-100', 'epochs': 10, '_wandb': {}}
2025-03-04 16:22:41,880 INFO    MainThread:22524 [wandb_init.py:init():784] starting backend
2025-03-04 16:22:41,880 INFO    MainThread:22524 [wandb_init.py:init():788] sending inform_init request
2025-03-04 16:22:41,883 INFO    MainThread:22524 [backend.py:_multiprocessing_setup():97] multiprocessing start_methods=spawn, using: spawn
2025-03-04 16:22:41,884 INFO    MainThread:22524 [wandb_init.py:init():803] backend started and connected
2025-03-04 16:22:41,885 INFO    MainThread:22524 [wandb_run.py:_label_probe_notebook():1204] probe notebook
2025-03-04 16:22:41,886 INFO    MainThread:22524 [wandb_run.py:_label_probe_notebook():1214] Unable to probe notebook: Expecting value: line 1 column 1 (char 0)
2025-03-04 16:22:41,886 INFO    MainThread:22524 [wandb_init.py:init():896] updated telemetry
2025-03-04 16:22:41,953 INFO    MainThread:22524 [wandb_init.py:init():920] communicating run to backend with 180.0 second timeout
2025-03-04 16:25:41,968 ERROR   MainThread:22524 [wandb_init.py:init():1481] error in wandb.init()
Traceback (most recent call last):
  File "c:\Users\sudha\AppData\Local\Programs\Python\Python311\Lib\asyncio\tasks.py", line 500, in wait_for
    return fut.result()
           ^^^^^^^^^^^^
  File "c:\Users\sudha\AppData\Local\Programs\Python\Python311\Lib\asyncio\locks.py", line 213, in wait
    await fut
asyncio.exceptions.CancelledError

The above exception was the direct cause of the following exception:

Traceback (most recent call last):
  File "c:\Users\sudha\AppData\Local\Programs\Python\Python311\Lib\site-packages\wandb\sdk\mailbox\handles.py", line 141, in wait_async
    await asyncio.wait_for(evt.wait(), timeout=timeout)
  File "c:\Users\sudha\AppData\Local\Programs\Python\Python311\Lib\asyncio\tasks.py", line 502, in wait_for
    raise exceptions.TimeoutError() from exc
TimeoutError

The above exception was the direct cause of the following exception:

Traceback (most recent call last):
  File "c:\Users\sudha\AppData\Local\Programs\Python\Python311\Lib\site-packages\wandb\sdk\wandb_init.py", line 946, in init
    result = wait_with_progress(
             ^^^^^^^^^^^^^^^^^^^
  File "c:\Users\sudha\AppData\Local\Programs\Python\Python311\Lib\site-packages\wandb\sdk\mailbox\wait_with_progress.py", line 23, in wait_with_progress
    return wait_all_with_progress(
           ^^^^^^^^^^^^^^^^^^^^^^^
  File "c:\Users\sudha\AppData\Local\Programs\Python\Python311\Lib\site-packages\wandb\sdk\mailbox\wait_with_progress.py", line 86, in wait_all_with_progress
    return asyncio_compat.run(progress_loop_with_timeout)
           ^^^^^^^^^^^^^^^^^^^^^^^^^^^^^^^^^^^^^^^^^^^^^^
  File "c:\Users\sudha\AppData\Local\Programs\Python\Python311\Lib\site-packages\wandb\sdk\lib\asyncio_compat.py", line 30, in run
    return future.result()
           ^^^^^^^^^^^^^^^
  File "c:\Users\sudha\AppData\Local\Programs\Python\Python311\Lib\concurrent\futures\_base.py", line 456, in result
    return self.__get_result()
           ^^^^^^^^^^^^^^^^^^^
  File "c:\Users\sudha\AppData\Local\Programs\Python\Python311\Lib\concurrent\futures\_base.py", line 401, in __get_result
    raise self._exception
  File "c:\Users\sudha\AppData\Local\Programs\Python\Python311\Lib\concurrent\futures\thread.py", line 58, in run
    result = self.fn(*self.args, **self.kwargs)
             ^^^^^^^^^^^^^^^^^^^^^^^^^^^^^^^^^^
  File "c:\Users\sudha\AppData\Local\Programs\Python\Python311\Lib\site-packages\wandb\sdk\lib\asyncio_compat.py", line 74, in run
    return asyncio.run(self._run_or_cancel(fn))
           ^^^^^^^^^^^^^^^^^^^^^^^^^^^^^^^^^^^^
  File "c:\Users\sudha\AppData\Local\Programs\Python\Python311\Lib\asyncio\runners.py", line 190, in run
    return runner.run(main)
           ^^^^^^^^^^^^^^^^
  File "c:\Users\sudha\AppData\Local\Programs\Python\Python311\Lib\asyncio\runners.py", line 118, in run
    return self._loop.run_until_complete(task)
           ^^^^^^^^^^^^^^^^^^^^^^^^^^^^^^^^^^^
  File "c:\Users\sudha\AppData\Local\Programs\Python\Python311\Lib\asyncio\base_events.py", line 654, in run_until_complete
    return future.result()
           ^^^^^^^^^^^^^^^
  File "c:\Users\sudha\AppData\Local\Programs\Python\Python311\Lib\site-packages\wandb\sdk\lib\asyncio_compat.py", line 98, in _run_or_cancel
    return fn_task.result()
           ^^^^^^^^^^^^^^^^
  File "c:\Users\sudha\AppData\Local\Programs\Python\Python311\Lib\site-packages\wandb\sdk\mailbox\wait_with_progress.py", line 81, in progress_loop_with_timeout
    return await _wait_handles_async(
           ^^^^^^^^^^^^^^^^^^^^^^^^^^
  File "c:\Users\sudha\AppData\Local\Programs\Python\Python311\Lib\site-packages\wandb\sdk\mailbox\wait_with_progress.py", line 129, in _wait_handles_async
    async with asyncio_compat.open_task_group() as task_group:
  File "c:\Users\sudha\AppData\Local\Programs\Python\Python311\Lib\contextlib.py", line 217, in __aexit__
    await anext(self.gen)
  File "c:\Users\sudha\AppData\Local\Programs\Python\Python311\Lib\site-packages\wandb\sdk\lib\asyncio_compat.py", line 190, in open_task_group
    await task_group._wait_all()
  File "c:\Users\sudha\AppData\Local\Programs\Python\Python311\Lib\site-packages\wandb\sdk\lib\asyncio_compat.py", line 159, in _wait_all
    raise exc
  File "c:\Users\sudha\AppData\Local\Programs\Python\Python311\Lib\site-packages\wandb\sdk\mailbox\wait_with_progress.py", line 127, in wait_single
    results[index] = await handle.wait_async(timeout=timeout)
                     ^^^^^^^^^^^^^^^^^^^^^^^^^^^^^^^^^^^^^^^^
  File "c:\Users\sudha\AppData\Local\Programs\Python\Python311\Lib\site-packages\wandb\sdk\mailbox\handles.py", line 150, in wait_async
    raise TimeoutError(
TimeoutError: Timed out waiting for response on lgx17c8uwwm2

During handling of the above exception, another exception occurred:

Traceback (most recent call last):
  File "c:\Users\sudha\AppData\Local\Programs\Python\Python311\Lib\site-packages\wandb\sdk\wandb_init.py", line 1471, in init
    return wi.init(run_settings, run_config)
           ^^^^^^^^^^^^^^^^^^^^^^^^^^^^^^^^^
  File "c:\Users\sudha\AppData\Local\Programs\Python\Python311\Lib\site-packages\wandb\sdk\wandb_init.py", line 959, in init
    raise CommError(
wandb.errors.errors.CommError: Run initialization has timed out after 180.0 sec. Please try increasing the timeout with the `init_timeout` setting: `wandb.init(settings=wandb.Settings(init_timeout=120))`.
2025-03-04 16:29:30,124 INFO    MainThread:22524 [wandb_init.py:setup_run_log_directory():647] Logging user logs to c:\Users\sudha\Desktop\My Data\Education\IITM\2nd sem\Intro to DL\Assignments\Deep-Learning-Assignmnent-1-DA24M023\wandb\run-20250304_162930-5a8xusn1\logs\debug.log
2025-03-04 16:29:30,124 INFO    MainThread:22524 [wandb_init.py:setup_run_log_directory():648] Logging internal logs to c:\Users\sudha\Desktop\My Data\Education\IITM\2nd sem\Intro to DL\Assignments\Deep-Learning-Assignmnent-1-DA24M023\wandb\run-20250304_162930-5a8xusn1\logs\debug-internal.log
2025-03-04 16:29:30,125 INFO    MainThread:22524 [wandb_init.py:init():761] calling init triggers
2025-03-04 16:29:30,125 INFO    MainThread:22524 [wandb_init.py:init():766] wandb.init called with sweep_config: {}
config: {'learning_rate': 0.02, 'architecture': 'CNN', 'dataset': 'CIFAR-100', 'epochs': 10, '_wandb': {}}
2025-03-04 16:29:30,125 INFO    MainThread:22524 [wandb_init.py:init():784] starting backend
2025-03-04 16:29:30,125 INFO    MainThread:22524 [wandb_init.py:init():788] sending inform_init request
2025-03-04 16:29:30,129 INFO    MainThread:22524 [backend.py:_multiprocessing_setup():97] multiprocessing start_methods=spawn, using: spawn
2025-03-04 16:29:30,133 INFO    MainThread:22524 [wandb_init.py:init():803] backend started and connected
2025-03-04 16:29:30,135 INFO    MainThread:22524 [wandb_run.py:_label_probe_notebook():1204] probe notebook
2025-03-04 16:29:30,136 INFO    MainThread:22524 [wandb_run.py:_label_probe_notebook():1214] Unable to probe notebook: Expecting value: line 1 column 1 (char 0)
2025-03-04 16:29:30,136 INFO    MainThread:22524 [wandb_init.py:init():896] updated telemetry
2025-03-04 16:29:30,209 INFO    MainThread:22524 [wandb_init.py:init():920] communicating run to backend with 180.0 second timeout
2025-03-04 16:32:30,238 ERROR   MainThread:22524 [wandb_init.py:init():1481] error in wandb.init()
Traceback (most recent call last):
  File "c:\Users\sudha\AppData\Local\Programs\Python\Python311\Lib\asyncio\tasks.py", line 500, in wait_for
    return fut.result()
           ^^^^^^^^^^^^
  File "c:\Users\sudha\AppData\Local\Programs\Python\Python311\Lib\asyncio\locks.py", line 213, in wait
    await fut
asyncio.exceptions.CancelledError

The above exception was the direct cause of the following exception:

Traceback (most recent call last):
  File "c:\Users\sudha\AppData\Local\Programs\Python\Python311\Lib\site-packages\wandb\sdk\mailbox\handles.py", line 141, in wait_async
    await asyncio.wait_for(evt.wait(), timeout=timeout)
  File "c:\Users\sudha\AppData\Local\Programs\Python\Python311\Lib\asyncio\tasks.py", line 502, in wait_for
    raise exceptions.TimeoutError() from exc
TimeoutError

The above exception was the direct cause of the following exception:

Traceback (most recent call last):
  File "c:\Users\sudha\AppData\Local\Programs\Python\Python311\Lib\site-packages\wandb\sdk\wandb_init.py", line 946, in init
    result = wait_with_progress(
             ^^^^^^^^^^^^^^^^^^^
  File "c:\Users\sudha\AppData\Local\Programs\Python\Python311\Lib\site-packages\wandb\sdk\mailbox\wait_with_progress.py", line 23, in wait_with_progress
    return wait_all_with_progress(
           ^^^^^^^^^^^^^^^^^^^^^^^
  File "c:\Users\sudha\AppData\Local\Programs\Python\Python311\Lib\site-packages\wandb\sdk\mailbox\wait_with_progress.py", line 86, in wait_all_with_progress
    return asyncio_compat.run(progress_loop_with_timeout)
           ^^^^^^^^^^^^^^^^^^^^^^^^^^^^^^^^^^^^^^^^^^^^^^
  File "c:\Users\sudha\AppData\Local\Programs\Python\Python311\Lib\site-packages\wandb\sdk\lib\asyncio_compat.py", line 30, in run
    return future.result()
           ^^^^^^^^^^^^^^^
  File "c:\Users\sudha\AppData\Local\Programs\Python\Python311\Lib\concurrent\futures\_base.py", line 456, in result
    return self.__get_result()
           ^^^^^^^^^^^^^^^^^^^
  File "c:\Users\sudha\AppData\Local\Programs\Python\Python311\Lib\concurrent\futures\_base.py", line 401, in __get_result
    raise self._exception
  File "c:\Users\sudha\AppData\Local\Programs\Python\Python311\Lib\concurrent\futures\thread.py", line 58, in run
    result = self.fn(*self.args, **self.kwargs)
             ^^^^^^^^^^^^^^^^^^^^^^^^^^^^^^^^^^
  File "c:\Users\sudha\AppData\Local\Programs\Python\Python311\Lib\site-packages\wandb\sdk\lib\asyncio_compat.py", line 74, in run
    return asyncio.run(self._run_or_cancel(fn))
           ^^^^^^^^^^^^^^^^^^^^^^^^^^^^^^^^^^^^
  File "c:\Users\sudha\AppData\Local\Programs\Python\Python311\Lib\asyncio\runners.py", line 190, in run
    return runner.run(main)
           ^^^^^^^^^^^^^^^^
  File "c:\Users\sudha\AppData\Local\Programs\Python\Python311\Lib\asyncio\runners.py", line 118, in run
    return self._loop.run_until_complete(task)
           ^^^^^^^^^^^^^^^^^^^^^^^^^^^^^^^^^^^
  File "c:\Users\sudha\AppData\Local\Programs\Python\Python311\Lib\asyncio\base_events.py", line 654, in run_until_complete
    return future.result()
           ^^^^^^^^^^^^^^^
  File "c:\Users\sudha\AppData\Local\Programs\Python\Python311\Lib\site-packages\wandb\sdk\lib\asyncio_compat.py", line 98, in _run_or_cancel
    return fn_task.result()
           ^^^^^^^^^^^^^^^^
  File "c:\Users\sudha\AppData\Local\Programs\Python\Python311\Lib\site-packages\wandb\sdk\mailbox\wait_with_progress.py", line 81, in progress_loop_with_timeout
    return await _wait_handles_async(
           ^^^^^^^^^^^^^^^^^^^^^^^^^^
  File "c:\Users\sudha\AppData\Local\Programs\Python\Python311\Lib\site-packages\wandb\sdk\mailbox\wait_with_progress.py", line 129, in _wait_handles_async
    async with asyncio_compat.open_task_group() as task_group:
  File "c:\Users\sudha\AppData\Local\Programs\Python\Python311\Lib\contextlib.py", line 217, in __aexit__
    await anext(self.gen)
  File "c:\Users\sudha\AppData\Local\Programs\Python\Python311\Lib\site-packages\wandb\sdk\lib\asyncio_compat.py", line 190, in open_task_group
    await task_group._wait_all()
  File "c:\Users\sudha\AppData\Local\Programs\Python\Python311\Lib\site-packages\wandb\sdk\lib\asyncio_compat.py", line 159, in _wait_all
    raise exc
  File "c:\Users\sudha\AppData\Local\Programs\Python\Python311\Lib\site-packages\wandb\sdk\mailbox\wait_with_progress.py", line 127, in wait_single
    results[index] = await handle.wait_async(timeout=timeout)
                     ^^^^^^^^^^^^^^^^^^^^^^^^^^^^^^^^^^^^^^^^
  File "c:\Users\sudha\AppData\Local\Programs\Python\Python311\Lib\site-packages\wandb\sdk\mailbox\handles.py", line 150, in wait_async
    raise TimeoutError(
TimeoutError: Timed out waiting for response on 2rpjbinpsmhi

During handling of the above exception, another exception occurred:

Traceback (most recent call last):
  File "c:\Users\sudha\AppData\Local\Programs\Python\Python311\Lib\site-packages\wandb\sdk\wandb_init.py", line 1471, in init
    return wi.init(run_settings, run_config)
           ^^^^^^^^^^^^^^^^^^^^^^^^^^^^^^^^^
  File "c:\Users\sudha\AppData\Local\Programs\Python\Python311\Lib\site-packages\wandb\sdk\wandb_init.py", line 959, in init
    raise CommError(
wandb.errors.errors.CommError: Run initialization has timed out after 180.0 sec. Please try increasing the timeout with the `init_timeout` setting: `wandb.init(settings=wandb.Settings(init_timeout=120))`.
2025-03-04 16:38:41,772 INFO    MainThread:22524 [wandb_init.py:setup_run_log_directory():647] Logging user logs to c:\Users\sudha\Desktop\My Data\Education\IITM\2nd sem\Intro to DL\Assignments\Deep-Learning-Assignmnent-1-DA24M023\wandb\run-20250304_163841-wg7xixby\logs\debug.log
2025-03-04 16:38:41,773 INFO    MainThread:22524 [wandb_init.py:setup_run_log_directory():648] Logging internal logs to c:\Users\sudha\Desktop\My Data\Education\IITM\2nd sem\Intro to DL\Assignments\Deep-Learning-Assignmnent-1-DA24M023\wandb\run-20250304_163841-wg7xixby\logs\debug-internal.log
2025-03-04 16:38:41,773 INFO    MainThread:22524 [wandb_init.py:init():761] calling init triggers
2025-03-04 16:38:41,773 INFO    MainThread:22524 [wandb_init.py:init():766] wandb.init called with sweep_config: {}
config: {'learning_rate': 0.02, 'architecture': 'CNN', 'dataset': 'CIFAR-100', 'epochs': 10, '_wandb': {}}
2025-03-04 16:38:41,774 INFO    MainThread:22524 [wandb_init.py:init():784] starting backend
2025-03-04 16:38:41,774 INFO    MainThread:22524 [wandb_init.py:init():788] sending inform_init request
2025-03-04 16:38:41,777 INFO    MainThread:22524 [backend.py:_multiprocessing_setup():97] multiprocessing start_methods=spawn, using: spawn
2025-03-04 16:38:41,778 INFO    MainThread:22524 [wandb_init.py:init():803] backend started and connected
2025-03-04 16:38:41,780 INFO    MainThread:22524 [wandb_run.py:_label_probe_notebook():1204] probe notebook
2025-03-04 16:38:41,781 INFO    MainThread:22524 [wandb_run.py:_label_probe_notebook():1214] Unable to probe notebook: Expecting value: line 1 column 1 (char 0)
2025-03-04 16:38:41,782 INFO    MainThread:22524 [wandb_init.py:init():896] updated telemetry
2025-03-04 16:38:41,860 INFO    MainThread:22524 [wandb_init.py:init():920] communicating run to backend with 90.0 second timeout
2025-03-04 16:40:11,859 ERROR   MainThread:22524 [wandb_init.py:init():1481] error in wandb.init()
Traceback (most recent call last):
  File "c:\Users\sudha\AppData\Local\Programs\Python\Python311\Lib\asyncio\tasks.py", line 500, in wait_for
    return fut.result()
           ^^^^^^^^^^^^
  File "c:\Users\sudha\AppData\Local\Programs\Python\Python311\Lib\asyncio\locks.py", line 213, in wait
    await fut
asyncio.exceptions.CancelledError

The above exception was the direct cause of the following exception:

Traceback (most recent call last):
  File "c:\Users\sudha\AppData\Local\Programs\Python\Python311\Lib\site-packages\wandb\sdk\mailbox\handles.py", line 141, in wait_async
    await asyncio.wait_for(evt.wait(), timeout=timeout)
  File "c:\Users\sudha\AppData\Local\Programs\Python\Python311\Lib\asyncio\tasks.py", line 502, in wait_for
    raise exceptions.TimeoutError() from exc
TimeoutError

The above exception was the direct cause of the following exception:

Traceback (most recent call last):
  File "c:\Users\sudha\AppData\Local\Programs\Python\Python311\Lib\site-packages\wandb\sdk\wandb_init.py", line 946, in init
    result = wait_with_progress(
             ^^^^^^^^^^^^^^^^^^^
  File "c:\Users\sudha\AppData\Local\Programs\Python\Python311\Lib\site-packages\wandb\sdk\mailbox\wait_with_progress.py", line 23, in wait_with_progress
    return wait_all_with_progress(
           ^^^^^^^^^^^^^^^^^^^^^^^
  File "c:\Users\sudha\AppData\Local\Programs\Python\Python311\Lib\site-packages\wandb\sdk\mailbox\wait_with_progress.py", line 86, in wait_all_with_progress
    return asyncio_compat.run(progress_loop_with_timeout)
           ^^^^^^^^^^^^^^^^^^^^^^^^^^^^^^^^^^^^^^^^^^^^^^
  File "c:\Users\sudha\AppData\Local\Programs\Python\Python311\Lib\site-packages\wandb\sdk\lib\asyncio_compat.py", line 30, in run
    return future.result()
           ^^^^^^^^^^^^^^^
  File "c:\Users\sudha\AppData\Local\Programs\Python\Python311\Lib\concurrent\futures\_base.py", line 456, in result
    return self.__get_result()
           ^^^^^^^^^^^^^^^^^^^
  File "c:\Users\sudha\AppData\Local\Programs\Python\Python311\Lib\concurrent\futures\_base.py", line 401, in __get_result
    raise self._exception
  File "c:\Users\sudha\AppData\Local\Programs\Python\Python311\Lib\concurrent\futures\thread.py", line 58, in run
    result = self.fn(*self.args, **self.kwargs)
             ^^^^^^^^^^^^^^^^^^^^^^^^^^^^^^^^^^
  File "c:\Users\sudha\AppData\Local\Programs\Python\Python311\Lib\site-packages\wandb\sdk\lib\asyncio_compat.py", line 74, in run
    return asyncio.run(self._run_or_cancel(fn))
           ^^^^^^^^^^^^^^^^^^^^^^^^^^^^^^^^^^^^
  File "c:\Users\sudha\AppData\Local\Programs\Python\Python311\Lib\asyncio\runners.py", line 190, in run
    return runner.run(main)
           ^^^^^^^^^^^^^^^^
  File "c:\Users\sudha\AppData\Local\Programs\Python\Python311\Lib\asyncio\runners.py", line 118, in run
    return self._loop.run_until_complete(task)
           ^^^^^^^^^^^^^^^^^^^^^^^^^^^^^^^^^^^
  File "c:\Users\sudha\AppData\Local\Programs\Python\Python311\Lib\asyncio\base_events.py", line 654, in run_until_complete
    return future.result()
           ^^^^^^^^^^^^^^^
  File "c:\Users\sudha\AppData\Local\Programs\Python\Python311\Lib\site-packages\wandb\sdk\lib\asyncio_compat.py", line 98, in _run_or_cancel
    return fn_task.result()
           ^^^^^^^^^^^^^^^^
  File "c:\Users\sudha\AppData\Local\Programs\Python\Python311\Lib\site-packages\wandb\sdk\mailbox\wait_with_progress.py", line 81, in progress_loop_with_timeout
    return await _wait_handles_async(
           ^^^^^^^^^^^^^^^^^^^^^^^^^^
  File "c:\Users\sudha\AppData\Local\Programs\Python\Python311\Lib\site-packages\wandb\sdk\mailbox\wait_with_progress.py", line 129, in _wait_handles_async
    async with asyncio_compat.open_task_group() as task_group:
  File "c:\Users\sudha\AppData\Local\Programs\Python\Python311\Lib\contextlib.py", line 217, in __aexit__
    await anext(self.gen)
  File "c:\Users\sudha\AppData\Local\Programs\Python\Python311\Lib\site-packages\wandb\sdk\lib\asyncio_compat.py", line 190, in open_task_group
    await task_group._wait_all()
  File "c:\Users\sudha\AppData\Local\Programs\Python\Python311\Lib\site-packages\wandb\sdk\lib\asyncio_compat.py", line 159, in _wait_all
    raise exc
  File "c:\Users\sudha\AppData\Local\Programs\Python\Python311\Lib\site-packages\wandb\sdk\mailbox\wait_with_progress.py", line 127, in wait_single
    results[index] = await handle.wait_async(timeout=timeout)
                     ^^^^^^^^^^^^^^^^^^^^^^^^^^^^^^^^^^^^^^^^
  File "c:\Users\sudha\AppData\Local\Programs\Python\Python311\Lib\site-packages\wandb\sdk\mailbox\handles.py", line 150, in wait_async
    raise TimeoutError(
TimeoutError: Timed out waiting for response on fq4u8ecnqj36

During handling of the above exception, another exception occurred:

Traceback (most recent call last):
  File "c:\Users\sudha\AppData\Local\Programs\Python\Python311\Lib\site-packages\wandb\sdk\wandb_init.py", line 1471, in init
    return wi.init(run_settings, run_config)
           ^^^^^^^^^^^^^^^^^^^^^^^^^^^^^^^^^
  File "c:\Users\sudha\AppData\Local\Programs\Python\Python311\Lib\site-packages\wandb\sdk\wandb_init.py", line 959, in init
    raise CommError(
wandb.errors.errors.CommError: Run initialization has timed out after 90.0 sec. Please try increasing the timeout with the `init_timeout` setting: `wandb.init(settings=wandb.Settings(init_timeout=120))`.
2025-03-04 16:50:54,885 INFO    MainThread:22524 [wandb_init.py:setup_run_log_directory():647] Logging user logs to c:\Users\sudha\Desktop\My Data\Education\IITM\2nd sem\Intro to DL\Assignments\Deep-Learning-Assignmnent-1-DA24M023\wandb\run-20250304_165054-vwaswjkw\logs\debug.log
2025-03-04 16:50:54,886 INFO    MainThread:22524 [wandb_init.py:setup_run_log_directory():648] Logging internal logs to c:\Users\sudha\Desktop\My Data\Education\IITM\2nd sem\Intro to DL\Assignments\Deep-Learning-Assignmnent-1-DA24M023\wandb\run-20250304_165054-vwaswjkw\logs\debug-internal.log
2025-03-04 16:50:54,887 INFO    MainThread:22524 [wandb_init.py:init():761] calling init triggers
2025-03-04 16:50:54,887 INFO    MainThread:22524 [wandb_init.py:init():766] wandb.init called with sweep_config: {}
config: {'learning_rate': 0.02, 'architecture': 'CNN', 'dataset': 'CIFAR-100', 'epochs': 10, '_wandb': {}}
2025-03-04 16:50:54,887 INFO    MainThread:22524 [wandb_init.py:init():784] starting backend
2025-03-04 16:50:54,888 INFO    MainThread:22524 [wandb_init.py:init():788] sending inform_init request
2025-03-04 16:50:54,891 INFO    MainThread:22524 [backend.py:_multiprocessing_setup():97] multiprocessing start_methods=spawn, using: spawn
2025-03-04 16:50:54,892 INFO    MainThread:22524 [wandb_init.py:init():803] backend started and connected
2025-03-04 16:50:54,894 INFO    MainThread:22524 [wandb_run.py:_label_probe_notebook():1204] probe notebook
2025-03-04 16:50:54,896 INFO    MainThread:22524 [wandb_init.py:init():896] updated telemetry
2025-03-04 16:50:54,970 INFO    MainThread:22524 [wandb_init.py:init():920] communicating run to backend with 90.0 second timeout
2025-03-04 16:52:24,975 ERROR   MainThread:22524 [wandb_init.py:init():1481] error in wandb.init()
Traceback (most recent call last):
  File "c:\Users\sudha\AppData\Local\Programs\Python\Python311\Lib\asyncio\tasks.py", line 500, in wait_for
    return fut.result()
           ^^^^^^^^^^^^
  File "c:\Users\sudha\AppData\Local\Programs\Python\Python311\Lib\asyncio\locks.py", line 213, in wait
    await fut
asyncio.exceptions.CancelledError

The above exception was the direct cause of the following exception:

Traceback (most recent call last):
  File "c:\Users\sudha\AppData\Local\Programs\Python\Python311\Lib\site-packages\wandb\sdk\mailbox\handles.py", line 141, in wait_async
    await asyncio.wait_for(evt.wait(), timeout=timeout)
  File "c:\Users\sudha\AppData\Local\Programs\Python\Python311\Lib\asyncio\tasks.py", line 502, in wait_for
    raise exceptions.TimeoutError() from exc
TimeoutError

The above exception was the direct cause of the following exception:

Traceback (most recent call last):
  File "c:\Users\sudha\AppData\Local\Programs\Python\Python311\Lib\site-packages\wandb\sdk\wandb_init.py", line 946, in init
    result = wait_with_progress(
             ^^^^^^^^^^^^^^^^^^^
  File "c:\Users\sudha\AppData\Local\Programs\Python\Python311\Lib\site-packages\wandb\sdk\mailbox\wait_with_progress.py", line 23, in wait_with_progress
    return wait_all_with_progress(
           ^^^^^^^^^^^^^^^^^^^^^^^
  File "c:\Users\sudha\AppData\Local\Programs\Python\Python311\Lib\site-packages\wandb\sdk\mailbox\wait_with_progress.py", line 86, in wait_all_with_progress
    return asyncio_compat.run(progress_loop_with_timeout)
           ^^^^^^^^^^^^^^^^^^^^^^^^^^^^^^^^^^^^^^^^^^^^^^
  File "c:\Users\sudha\AppData\Local\Programs\Python\Python311\Lib\site-packages\wandb\sdk\lib\asyncio_compat.py", line 30, in run
    return future.result()
           ^^^^^^^^^^^^^^^
  File "c:\Users\sudha\AppData\Local\Programs\Python\Python311\Lib\concurrent\futures\_base.py", line 456, in result
    return self.__get_result()
           ^^^^^^^^^^^^^^^^^^^
  File "c:\Users\sudha\AppData\Local\Programs\Python\Python311\Lib\concurrent\futures\_base.py", line 401, in __get_result
    raise self._exception
  File "c:\Users\sudha\AppData\Local\Programs\Python\Python311\Lib\concurrent\futures\thread.py", line 58, in run
    result = self.fn(*self.args, **self.kwargs)
             ^^^^^^^^^^^^^^^^^^^^^^^^^^^^^^^^^^
  File "c:\Users\sudha\AppData\Local\Programs\Python\Python311\Lib\site-packages\wandb\sdk\lib\asyncio_compat.py", line 74, in run
    return asyncio.run(self._run_or_cancel(fn))
           ^^^^^^^^^^^^^^^^^^^^^^^^^^^^^^^^^^^^
  File "c:\Users\sudha\AppData\Local\Programs\Python\Python311\Lib\asyncio\runners.py", line 190, in run
    return runner.run(main)
           ^^^^^^^^^^^^^^^^
  File "c:\Users\sudha\AppData\Local\Programs\Python\Python311\Lib\asyncio\runners.py", line 118, in run
    return self._loop.run_until_complete(task)
           ^^^^^^^^^^^^^^^^^^^^^^^^^^^^^^^^^^^
  File "c:\Users\sudha\AppData\Local\Programs\Python\Python311\Lib\asyncio\base_events.py", line 654, in run_until_complete
    return future.result()
           ^^^^^^^^^^^^^^^
  File "c:\Users\sudha\AppData\Local\Programs\Python\Python311\Lib\site-packages\wandb\sdk\lib\asyncio_compat.py", line 98, in _run_or_cancel
    return fn_task.result()
           ^^^^^^^^^^^^^^^^
  File "c:\Users\sudha\AppData\Local\Programs\Python\Python311\Lib\site-packages\wandb\sdk\mailbox\wait_with_progress.py", line 81, in progress_loop_with_timeout
    return await _wait_handles_async(
           ^^^^^^^^^^^^^^^^^^^^^^^^^^
  File "c:\Users\sudha\AppData\Local\Programs\Python\Python311\Lib\site-packages\wandb\sdk\mailbox\wait_with_progress.py", line 129, in _wait_handles_async
    async with asyncio_compat.open_task_group() as task_group:
  File "c:\Users\sudha\AppData\Local\Programs\Python\Python311\Lib\contextlib.py", line 217, in __aexit__
    await anext(self.gen)
  File "c:\Users\sudha\AppData\Local\Programs\Python\Python311\Lib\site-packages\wandb\sdk\lib\asyncio_compat.py", line 190, in open_task_group
    await task_group._wait_all()
  File "c:\Users\sudha\AppData\Local\Programs\Python\Python311\Lib\site-packages\wandb\sdk\lib\asyncio_compat.py", line 159, in _wait_all
    raise exc
  File "c:\Users\sudha\AppData\Local\Programs\Python\Python311\Lib\site-packages\wandb\sdk\mailbox\wait_with_progress.py", line 127, in wait_single
    results[index] = await handle.wait_async(timeout=timeout)
                     ^^^^^^^^^^^^^^^^^^^^^^^^^^^^^^^^^^^^^^^^
  File "c:\Users\sudha\AppData\Local\Programs\Python\Python311\Lib\site-packages\wandb\sdk\mailbox\handles.py", line 150, in wait_async
    raise TimeoutError(
TimeoutError: Timed out waiting for response on by5ohnajzvnv

During handling of the above exception, another exception occurred:

Traceback (most recent call last):
  File "c:\Users\sudha\AppData\Local\Programs\Python\Python311\Lib\site-packages\wandb\sdk\wandb_init.py", line 1471, in init
    return wi.init(run_settings, run_config)
           ^^^^^^^^^^^^^^^^^^^^^^^^^^^^^^^^^
  File "c:\Users\sudha\AppData\Local\Programs\Python\Python311\Lib\site-packages\wandb\sdk\wandb_init.py", line 959, in init
    raise CommError(
wandb.errors.errors.CommError: Run initialization has timed out after 90.0 sec. Please try increasing the timeout with the `init_timeout` setting: `wandb.init(settings=wandb.Settings(init_timeout=120))`.
2025-03-04 16:53:45,697 INFO    MainThread:22524 [wandb_init.py:setup_run_log_directory():647] Logging user logs to c:\Users\sudha\Desktop\My Data\Education\IITM\2nd sem\Intro to DL\Assignments\Deep-Learning-Assignmnent-1-DA24M023\wandb\run-20250304_165345-o131fq36\logs\debug.log
2025-03-04 16:53:45,698 INFO    MainThread:22524 [wandb_init.py:setup_run_log_directory():648] Logging internal logs to c:\Users\sudha\Desktop\My Data\Education\IITM\2nd sem\Intro to DL\Assignments\Deep-Learning-Assignmnent-1-DA24M023\wandb\run-20250304_165345-o131fq36\logs\debug-internal.log
2025-03-04 16:53:45,699 INFO    MainThread:22524 [wandb_init.py:init():761] calling init triggers
2025-03-04 16:53:45,699 INFO    MainThread:22524 [wandb_init.py:init():766] wandb.init called with sweep_config: {}
config: {'learning_rate': 0.02, 'architecture': 'CNN', 'dataset': 'CIFAR-100', 'epochs': 10, '_wandb': {}}
2025-03-04 16:53:45,700 INFO    MainThread:22524 [wandb_init.py:init():784] starting backend
2025-03-04 16:53:45,701 INFO    MainThread:22524 [wandb_init.py:init():788] sending inform_init request
2025-03-04 16:53:45,706 INFO    MainThread:22524 [backend.py:_multiprocessing_setup():97] multiprocessing start_methods=spawn, using: spawn
2025-03-04 16:53:45,712 INFO    MainThread:22524 [wandb_init.py:init():803] backend started and connected
2025-03-04 16:53:45,716 INFO    MainThread:22524 [wandb_run.py:_label_probe_notebook():1204] probe notebook
2025-03-04 16:53:45,717 INFO    MainThread:22524 [wandb_init.py:init():896] updated telemetry
2025-03-04 16:53:45,833 INFO    MainThread:22524 [wandb_init.py:init():920] communicating run to backend with 90.0 second timeout
2025-03-04 16:55:15,873 ERROR   MainThread:22524 [wandb_init.py:init():1481] error in wandb.init()
Traceback (most recent call last):
  File "c:\Users\sudha\AppData\Local\Programs\Python\Python311\Lib\asyncio\tasks.py", line 500, in wait_for
    return fut.result()
           ^^^^^^^^^^^^
  File "c:\Users\sudha\AppData\Local\Programs\Python\Python311\Lib\asyncio\locks.py", line 213, in wait
    await fut
asyncio.exceptions.CancelledError

The above exception was the direct cause of the following exception:

Traceback (most recent call last):
  File "c:\Users\sudha\AppData\Local\Programs\Python\Python311\Lib\site-packages\wandb\sdk\mailbox\handles.py", line 141, in wait_async
    await asyncio.wait_for(evt.wait(), timeout=timeout)
  File "c:\Users\sudha\AppData\Local\Programs\Python\Python311\Lib\asyncio\tasks.py", line 502, in wait_for
    raise exceptions.TimeoutError() from exc
TimeoutError

The above exception was the direct cause of the following exception:

Traceback (most recent call last):
  File "c:\Users\sudha\AppData\Local\Programs\Python\Python311\Lib\site-packages\wandb\sdk\wandb_init.py", line 946, in init
    result = wait_with_progress(
             ^^^^^^^^^^^^^^^^^^^
  File "c:\Users\sudha\AppData\Local\Programs\Python\Python311\Lib\site-packages\wandb\sdk\mailbox\wait_with_progress.py", line 23, in wait_with_progress
    return wait_all_with_progress(
           ^^^^^^^^^^^^^^^^^^^^^^^
  File "c:\Users\sudha\AppData\Local\Programs\Python\Python311\Lib\site-packages\wandb\sdk\mailbox\wait_with_progress.py", line 86, in wait_all_with_progress
    return asyncio_compat.run(progress_loop_with_timeout)
           ^^^^^^^^^^^^^^^^^^^^^^^^^^^^^^^^^^^^^^^^^^^^^^
  File "c:\Users\sudha\AppData\Local\Programs\Python\Python311\Lib\site-packages\wandb\sdk\lib\asyncio_compat.py", line 30, in run
    return future.result()
           ^^^^^^^^^^^^^^^
  File "c:\Users\sudha\AppData\Local\Programs\Python\Python311\Lib\concurrent\futures\_base.py", line 456, in result
    return self.__get_result()
           ^^^^^^^^^^^^^^^^^^^
  File "c:\Users\sudha\AppData\Local\Programs\Python\Python311\Lib\concurrent\futures\_base.py", line 401, in __get_result
    raise self._exception
  File "c:\Users\sudha\AppData\Local\Programs\Python\Python311\Lib\concurrent\futures\thread.py", line 58, in run
    result = self.fn(*self.args, **self.kwargs)
             ^^^^^^^^^^^^^^^^^^^^^^^^^^^^^^^^^^
  File "c:\Users\sudha\AppData\Local\Programs\Python\Python311\Lib\site-packages\wandb\sdk\lib\asyncio_compat.py", line 74, in run
    return asyncio.run(self._run_or_cancel(fn))
           ^^^^^^^^^^^^^^^^^^^^^^^^^^^^^^^^^^^^
  File "c:\Users\sudha\AppData\Local\Programs\Python\Python311\Lib\asyncio\runners.py", line 190, in run
    return runner.run(main)
           ^^^^^^^^^^^^^^^^
  File "c:\Users\sudha\AppData\Local\Programs\Python\Python311\Lib\asyncio\runners.py", line 118, in run
    return self._loop.run_until_complete(task)
           ^^^^^^^^^^^^^^^^^^^^^^^^^^^^^^^^^^^
  File "c:\Users\sudha\AppData\Local\Programs\Python\Python311\Lib\asyncio\base_events.py", line 654, in run_until_complete
    return future.result()
           ^^^^^^^^^^^^^^^
  File "c:\Users\sudha\AppData\Local\Programs\Python\Python311\Lib\site-packages\wandb\sdk\lib\asyncio_compat.py", line 98, in _run_or_cancel
    return fn_task.result()
           ^^^^^^^^^^^^^^^^
  File "c:\Users\sudha\AppData\Local\Programs\Python\Python311\Lib\site-packages\wandb\sdk\mailbox\wait_with_progress.py", line 81, in progress_loop_with_timeout
    return await _wait_handles_async(
           ^^^^^^^^^^^^^^^^^^^^^^^^^^
  File "c:\Users\sudha\AppData\Local\Programs\Python\Python311\Lib\site-packages\wandb\sdk\mailbox\wait_with_progress.py", line 129, in _wait_handles_async
    async with asyncio_compat.open_task_group() as task_group:
  File "c:\Users\sudha\AppData\Local\Programs\Python\Python311\Lib\contextlib.py", line 217, in __aexit__
    await anext(self.gen)
  File "c:\Users\sudha\AppData\Local\Programs\Python\Python311\Lib\site-packages\wandb\sdk\lib\asyncio_compat.py", line 190, in open_task_group
    await task_group._wait_all()
  File "c:\Users\sudha\AppData\Local\Programs\Python\Python311\Lib\site-packages\wandb\sdk\lib\asyncio_compat.py", line 159, in _wait_all
    raise exc
  File "c:\Users\sudha\AppData\Local\Programs\Python\Python311\Lib\site-packages\wandb\sdk\mailbox\wait_with_progress.py", line 127, in wait_single
    results[index] = await handle.wait_async(timeout=timeout)
                     ^^^^^^^^^^^^^^^^^^^^^^^^^^^^^^^^^^^^^^^^
  File "c:\Users\sudha\AppData\Local\Programs\Python\Python311\Lib\site-packages\wandb\sdk\mailbox\handles.py", line 150, in wait_async
    raise TimeoutError(
TimeoutError: Timed out waiting for response on zpok9hccyg52

During handling of the above exception, another exception occurred:

Traceback (most recent call last):
  File "c:\Users\sudha\AppData\Local\Programs\Python\Python311\Lib\site-packages\wandb\sdk\wandb_init.py", line 1471, in init
    return wi.init(run_settings, run_config)
           ^^^^^^^^^^^^^^^^^^^^^^^^^^^^^^^^^
  File "c:\Users\sudha\AppData\Local\Programs\Python\Python311\Lib\site-packages\wandb\sdk\wandb_init.py", line 959, in init
    raise CommError(
wandb.errors.errors.CommError: Run initialization has timed out after 90.0 sec. Please try increasing the timeout with the `init_timeout` setting: `wandb.init(settings=wandb.Settings(init_timeout=120))`.
2025-03-04 17:01:00,674 WARNING MsgRouterThr:22524 [router.py:message_loop():77] message_loop has been closed
Traceback (most recent call last):
  File "c:\Users\sudha\AppData\Local\Programs\Python\Python311\Lib\site-packages\wandb\sdk\lib\sock_client.py", line 258, in _read_packet_bytes
    data = self._sock.recv(self._bufsize)
           ^^^^^^^^^^^^^^^^^^^^^^^^^^^^^^
BlockingIOError: [WinError 10035] A non-blocking socket operation could not be completed immediately

The above exception was the direct cause of the following exception:

Traceback (most recent call last):
  File "c:\Users\sudha\AppData\Local\Programs\Python\Python311\Lib\site-packages\wandb\sdk\interface\router_sock.py", line 28, in _read_message
    resp = self._sock_client.read_server_response(timeout=1)
           ^^^^^^^^^^^^^^^^^^^^^^^^^^^^^^^^^^^^^^^^^^^^^^^^^
  File "c:\Users\sudha\AppData\Local\Programs\Python\Python311\Lib\site-packages\wandb\sdk\lib\sock_client.py", line 285, in read_server_response
    data = self._read_packet_bytes(timeout=timeout)
           ^^^^^^^^^^^^^^^^^^^^^^^^^^^^^^^^^^^^^^^^
  File "c:\Users\sudha\AppData\Local\Programs\Python\Python311\Lib\site-packages\wandb\sdk\lib\sock_client.py", line 262, in _read_packet_bytes
    raise SockClientClosedError from e
wandb.sdk.lib.sock_client.SockClientClosedError

The above exception was the direct cause of the following exception:

Traceback (most recent call last):
  File "c:\Users\sudha\AppData\Local\Programs\Python\Python311\Lib\site-packages\wandb\sdk\interface\router.py", line 70, in message_loop
    msg = self._read_message()
          ^^^^^^^^^^^^^^^^^^^^
  File "c:\Users\sudha\AppData\Local\Programs\Python\Python311\Lib\site-packages\wandb\sdk\interface\router_sock.py", line 30, in _read_message
    raise MessageRouterClosedError from e
wandb.sdk.interface.router.MessageRouterClosedError
2025-03-04 17:01:00,682 INFO    MsgRouterThr:22524 [mailbox.py:close():115] Closing mailbox, abandoning 2 handles.
