2025-03-09 17:16:21,472 INFO    MainThread:28184 [wandb_setup.py:_flush():67] Current SDK version is 0.19.7
2025-03-09 17:16:21,473 INFO    MainThread:28184 [wandb_setup.py:_flush():67] Configure stats pid to 28184
2025-03-09 17:16:21,473 INFO    MainThread:28184 [wandb_setup.py:_flush():67] Loading settings from C:\Users\sudha\.config\wandb\settings
2025-03-09 17:16:21,473 INFO    MainThread:28184 [wandb_setup.py:_flush():67] Loading settings from C:\Users\sudha\Desktop\My Data\Education\IITM\2nd sem\Intro to DL\Assignments\Deep-Learning-Assignmnent-1-DA24M023\wandb\settings
2025-03-09 17:16:21,473 INFO    MainThread:28184 [wandb_setup.py:_flush():67] Loading settings from environment variables
2025-03-09 17:16:21,473 INFO    MainThread:28184 [wandb_init.py:setup_run_log_directory():647] Logging user logs to C:\Users\sudha\Desktop\My Data\Education\IITM\2nd sem\Intro to DL\Assignments\Deep-Learning-Assignmnent-1-DA24M023\wandb\run-20250309_171621-c3ttg274\logs\debug.log
2025-03-09 17:16:21,474 INFO    MainThread:28184 [wandb_init.py:setup_run_log_directory():648] Logging internal logs to C:\Users\sudha\Desktop\My Data\Education\IITM\2nd sem\Intro to DL\Assignments\Deep-Learning-Assignmnent-1-DA24M023\wandb\run-20250309_171621-c3ttg274\logs\debug-internal.log
2025-03-09 17:16:21,474 INFO    MainThread:28184 [wandb_init.py:init():761] calling init triggers
2025-03-09 17:16:21,474 INFO    MainThread:28184 [wandb_init.py:init():766] wandb.init called with sweep_config: {}
config: {'_wandb': {}}
2025-03-09 17:16:21,474 INFO    MainThread:28184 [wandb_init.py:init():784] starting backend
2025-03-09 17:16:21,474 INFO    MainThread:28184 [wandb_init.py:init():788] sending inform_init request
2025-03-09 17:16:21,502 INFO    MainThread:28184 [backend.py:_multiprocessing_setup():97] multiprocessing start_methods=spawn, using: spawn
2025-03-09 17:16:21,503 INFO    MainThread:28184 [wandb_init.py:init():803] backend started and connected
2025-03-09 17:16:21,504 INFO    MainThread:28184 [wandb_init.py:init():896] updated telemetry
2025-03-09 17:16:21,571 INFO    MainThread:28184 [wandb_init.py:init():920] communicating run to backend with 90.0 second timeout
2025-03-09 17:16:22,589 ERROR   MainThread:28184 [wandb_init.py:init():1481] error in wandb.init()
Traceback (most recent call last):
  File "C:\Users\sudha\AppData\Local\Programs\Python\Python311\Lib\site-packages\wandb\sdk\wandb_init.py", line 1471, in init
    return wi.init(run_settings, run_config)
           ^^^^^^^^^^^^^^^^^^^^^^^^^^^^^^^^^
  File "C:\Users\sudha\AppData\Local\Programs\Python\Python311\Lib\site-packages\wandb\sdk\wandb_init.py", line 968, in init
    raise error
wandb.errors.errors.CommError: failed to upsert bucket: returned error 403 Forbidden: {"errors":[{"message":"permission denied","path":["upsertBucket"],"extensions":{"code":"PERMISSION_ERROR"}}],"data":{"upsertBucket":null}}
2025-03-09 17:16:22,604 WARNING MsgRouterThr:28184 [router.py:message_loop():77] message_loop has been closed
Traceback (most recent call last):
  File "C:\Users\sudha\AppData\Local\Programs\Python\Python311\Lib\site-packages\wandb\sdk\interface\router_sock.py", line 28, in _read_message
    resp = self._sock_client.read_server_response(timeout=1)
           ^^^^^^^^^^^^^^^^^^^^^^^^^^^^^^^^^^^^^^^^^^^^^^^^^
  File "C:\Users\sudha\AppData\Local\Programs\Python\Python311\Lib\site-packages\wandb\sdk\lib\sock_client.py", line 285, in read_server_response
    data = self._read_packet_bytes(timeout=timeout)
           ^^^^^^^^^^^^^^^^^^^^^^^^^^^^^^^^^^^^^^^^
  File "C:\Users\sudha\AppData\Local\Programs\Python\Python311\Lib\site-packages\wandb\sdk\lib\sock_client.py", line 270, in _read_packet_bytes
    raise SockClientClosedError
wandb.sdk.lib.sock_client.SockClientClosedError

The above exception was the direct cause of the following exception:

Traceback (most recent call last):
  File "C:\Users\sudha\AppData\Local\Programs\Python\Python311\Lib\site-packages\wandb\sdk\interface\router.py", line 70, in message_loop
    msg = self._read_message()
          ^^^^^^^^^^^^^^^^^^^^
  File "C:\Users\sudha\AppData\Local\Programs\Python\Python311\Lib\site-packages\wandb\sdk\interface\router_sock.py", line 30, in _read_message
    raise MessageRouterClosedError from e
wandb.sdk.interface.router.MessageRouterClosedError
2025-03-09 17:16:22,606 INFO    MsgRouterThr:28184 [mailbox.py:close():115] Closing mailbox, abandoning 0 handles.
