2025-03-09 18:12:04,605 INFO    MainThread:20892 [wandb_setup.py:_flush():67] Current SDK version is 0.19.7
2025-03-09 18:12:04,606 INFO    MainThread:20892 [wandb_setup.py:_flush():67] Configure stats pid to 20892
2025-03-09 18:12:04,606 INFO    MainThread:20892 [wandb_setup.py:_flush():67] Loading settings from C:\Users\sudha\.config\wandb\settings
2025-03-09 18:12:04,606 INFO    MainThread:20892 [wandb_setup.py:_flush():67] Loading settings from C:\Users\sudha\Desktop\My Data\Education\IITM\2nd sem\Intro to DL\Assignments\Deep-Learning-Assignmnent-1-DA24M023\wandb\settings
2025-03-09 18:12:04,606 INFO    MainThread:20892 [wandb_setup.py:_flush():67] Loading settings from environment variables
2025-03-09 18:12:04,606 INFO    MainThread:20892 [wandb_init.py:setup_run_log_directory():647] Logging user logs to C:\Users\sudha\Desktop\My Data\Education\IITM\2nd sem\Intro to DL\Assignments\Deep-Learning-Assignmnent-1-DA24M023\wandb\run-20250309_181204-ghfewd1e\logs\debug.log
2025-03-09 18:12:04,606 INFO    MainThread:20892 [wandb_init.py:setup_run_log_directory():648] Logging internal logs to C:\Users\sudha\Desktop\My Data\Education\IITM\2nd sem\Intro to DL\Assignments\Deep-Learning-Assignmnent-1-DA24M023\wandb\run-20250309_181204-ghfewd1e\logs\debug-internal.log
2025-03-09 18:12:04,606 INFO    MainThread:20892 [wandb_init.py:init():761] calling init triggers
2025-03-09 18:12:04,606 INFO    MainThread:20892 [wandb_init.py:init():766] wandb.init called with sweep_config: {}
config: {'_wandb': {}}
2025-03-09 18:12:04,606 INFO    MainThread:20892 [wandb_init.py:init():784] starting backend
2025-03-09 18:12:04,606 INFO    MainThread:20892 [wandb_init.py:init():788] sending inform_init request
2025-03-09 18:12:04,630 INFO    MainThread:20892 [backend.py:_multiprocessing_setup():97] multiprocessing start_methods=spawn, using: spawn
2025-03-09 18:12:04,631 INFO    MainThread:20892 [wandb_init.py:init():803] backend started and connected
2025-03-09 18:12:04,632 INFO    MainThread:20892 [wandb_init.py:init():896] updated telemetry
2025-03-09 18:12:04,696 INFO    MainThread:20892 [wandb_init.py:init():920] communicating run to backend with 90.0 second timeout
2025-03-09 18:12:05,768 INFO    MainThread:20892 [wandb_init.py:init():995] starting run threads in backend
2025-03-09 18:12:05,929 INFO    MainThread:20892 [wandb_run.py:_console_start():2377] atexit reg
2025-03-09 18:12:05,929 INFO    MainThread:20892 [wandb_run.py:_redirect():2227] redirect: wrap_raw
2025-03-09 18:12:05,930 INFO    MainThread:20892 [wandb_run.py:_redirect():2292] Wrapping output streams.
2025-03-09 18:12:05,930 INFO    MainThread:20892 [wandb_run.py:_redirect():2317] Redirects installed.
2025-03-09 18:12:05,932 INFO    MainThread:20892 [wandb_init.py:init():1037] run started, returning control to user process
2025-03-09 18:12:05,932 INFO    MainThread:20892 [wandb_run.py:_config_callback():1261] config_cb None None {'hidden_layers': 3, 'hidden_size': 128, 'activation': 'tanh', 'optimizer': 'adam', 'learning_rate': 0.0001, 'weight_decay': 0, 'batch_size': 16, 'epochs': 1, 'weight_init': 'Xavier', 'dataset': 'fashion_mnist', 'loss_fn': 'mean_squeared_error'}
2025-03-09 18:12:06,022 WARNING MsgRouterThr:20892 [router.py:message_loop():77] message_loop has been closed
Traceback (most recent call last):
  File "C:\Users\sudha\AppData\Local\Programs\Python\Python311\Lib\site-packages\wandb\sdk\interface\router_sock.py", line 28, in _read_message
    resp = self._sock_client.read_server_response(timeout=1)
           ^^^^^^^^^^^^^^^^^^^^^^^^^^^^^^^^^^^^^^^^^^^^^^^^^
  File "C:\Users\sudha\AppData\Local\Programs\Python\Python311\Lib\site-packages\wandb\sdk\lib\sock_client.py", line 285, in read_server_response
    data = self._read_packet_bytes(timeout=timeout)
           ^^^^^^^^^^^^^^^^^^^^^^^^^^^^^^^^^^^^^^^^
  File "C:\Users\sudha\AppData\Local\Programs\Python\Python311\Lib\site-packages\wandb\sdk\lib\sock_client.py", line 270, in _read_packet_bytes
    raise SockClientClosedError
wandb.sdk.lib.sock_client.SockClientClosedError

The above exception was the direct cause of the following exception:

Traceback (most recent call last):
  File "C:\Users\sudha\AppData\Local\Programs\Python\Python311\Lib\site-packages\wandb\sdk\interface\router.py", line 70, in message_loop
    msg = self._read_message()
          ^^^^^^^^^^^^^^^^^^^^
  File "C:\Users\sudha\AppData\Local\Programs\Python\Python311\Lib\site-packages\wandb\sdk\interface\router_sock.py", line 30, in _read_message
    raise MessageRouterClosedError from e
wandb.sdk.interface.router.MessageRouterClosedError
2025-03-09 18:12:06,025 INFO    MsgRouterThr:20892 [mailbox.py:close():115] Closing mailbox, abandoning 2 handles.
