Traceback (most recent call last):
  File "C:\Users\sudha\AppData\Local\Programs\Python\Python311\Lib\site-packages\wandb\sdk\wandb_config.py", line 165, in __getattr__
    return self.__getitem__(key)
           ^^^^^^^^^^^^^^^^^^^^^
  File "C:\Users\sudha\AppData\Local\Programs\Python\Python311\Lib\site-packages\wandb\sdk\wandb_config.py", line 130, in __getitem__
    return self._items[key]
           ~~~~~~~~~~~^^^^^
KeyError: 'loss'

The above exception was the direct cause of the following exception:

Traceback (most recent call last):
  File "C:\Users\sudha\Desktop\My Data\Education\IITM\2nd sem\Intro to DL\Assignments\Deep-Learning-Assignmnent-1-DA24M023\experiment.py", line 38, in run_experiment
    train(model, X_train, y_train, config.batch_size, config.epochs, X_val, y_val, loss_fn=config.loss)
                                                                                           ^^^^^^^^^^^
  File "C:\Users\sudha\AppData\Local\Programs\Python\Python311\Lib\site-packages\wandb\sdk\wandb_config.py", line 167, in __getattr__
    raise AttributeError(
AttributeError: <class 'wandb.sdk.wandb_config.Config'> object has no attribute 'loss'
